Watching for file changes with StatReloader
Exception in thread django-main-thread:
Traceback (most recent call last):
  File "/usr/lib/python3.10/threading.py", line 1016, in _bootstrap_inner
    self.run()
  File "/usr/lib/python3.10/threading.py", line 953, in run
    self._target(*self._args, **self._kwargs)
  File "/usr/local/lib/python3.10/dist-packages/django/utils/autoreload.py", line 64, in wrapper
    fn(*args, **kwargs)
  File "/usr/local/lib/python3.10/dist-packages/django/core/management/commands/runserver.py", line 126, in inner_run
    autoreload.raise_last_exception()
  File "/usr/local/lib/python3.10/dist-packages/django/utils/autoreload.py", line 87, in raise_last_exception
    raise _exception[1]
  File "/usr/local/lib/python3.10/dist-packages/django/core/management/__init__.py", line 394, in execute
    autoreload.check_errors(django.setup)()
  File "/usr/local/lib/python3.10/dist-packages/django/utils/autoreload.py", line 64, in wrapper
    fn(*args, **kwargs)
  File "/usr/local/lib/python3.10/dist-packages/django/__init__.py", line 24, in setup
    apps.populate(settings.INSTALLED_APPS)
  File "/usr/local/lib/python3.10/dist-packages/django/apps/registry.py", line 93, in populate
    raise ImproperlyConfigured(
django.core.exceptions.ImproperlyConfigured: Application labels aren't unique, duplicates: messages
/home/user/tubonge_project/tubonge_backend/tubonge_backend/settings.py changed, reloading.
Watching for file changes with StatReloader
Exception in thread django-main-thread:
Traceback (most recent call last):
  File "/usr/local/lib/python3.10/dist-packages/django/apps/config.py", line 210, in create
    app_module = import_module(app_name)
  File "/usr/lib/python3.10/importlib/__init__.py", line 126, in import_module
    return _bootstrap._gcd_import(name[level:], package, level)
  File "<frozen importlib._bootstrap>", line 1050, in _gcd_import
  File "<frozen importlib._bootstrap>", line 1027, in _find_and_load
  File "<frozen importlib._bootstrap>", line 1004, in _find_and_load_unlocked
ModuleNotFoundError: No module named 'messages'

During handling of the above exception, another exception occurred:

Traceback (most recent call last):
  File "/usr/lib/python3.10/threading.py", line 1016, in _bootstrap_inner
    self.run()
  File "/usr/lib/python3.10/threading.py", line 953, in run
    self._target(*self._args, **self._kwargs)
  File "/usr/local/lib/python3.10/dist-packages/django/utils/autoreload.py", line 64, in wrapper
    fn(*args, **kwargs)
  File "/usr/local/lib/python3.10/dist-packages/django/core/management/commands/runserver.py", line 126, in inner_run
    autoreload.raise_last_exception()
  File "/usr/local/lib/python3.10/dist-packages/django/utils/autoreload.py", line 87, in raise_last_exception
    raise _exception[1]
  File "/usr/local/lib/python3.10/dist-packages/django/core/management/__init__.py", line 394, in execute
    autoreload.check_errors(django.setup)()
  File "/usr/local/lib/python3.10/dist-packages/django/utils/autoreload.py", line 64, in wrapper
    fn(*args, **kwargs)
  File "/usr/local/lib/python3.10/dist-packages/django/__init__.py", line 24, in setup
    apps.populate(settings.INSTALLED_APPS)
  File "/usr/local/lib/python3.10/dist-packages/django/apps/registry.py", line 91, in populate
    app_config = AppConfig.create(entry)
  File "/usr/local/lib/python3.10/dist-packages/django/apps/config.py", line 212, in create
    raise ImproperlyConfigured(
django.core.exceptions.ImproperlyConfigured: Cannot import 'messages'. Check that 'chat.apps.MessagesConfig.name' is correct.
