Watching for file changes with StatReloader
Exception in thread django-main-thread:
Traceback (most recent call last):
  File "/usr/lib/python3.10/threading.py", line 1016, in _bootstrap_inner
    self.run()
  File "/usr/lib/python3.10/threading.py", line 953, in run
    self._target(*self._args, **self._kwargs)
  File "/usr/local/lib/python3.10/dist-packages/django/utils/autoreload.py", line 64, in wrapper
    fn(*args, **kwargs)
  File "/usr/local/lib/python3.10/dist-packages/django/core/management/commands/runserver.py", line 134, in inner_run
    self.check(display_num_errors=True)
  File "/usr/local/lib/python3.10/dist-packages/django/core/management/base.py", line 563, in check
    raise SystemCheckError(msg)
django.core.management.base.SystemCheckError: SystemCheckError: System check identified some issues:

ERRORS:
auth.User.groups: (fields.E304) Reverse accessor 'Group.user_set' for 'auth.User.groups' clashes with reverse accessor for 'users.CustomUser.groups'.
	HINT: Add or change a related_name argument to the definition for 'auth.User.groups' or 'users.CustomUser.groups'.
auth.User.user_permissions: (fields.E304) Reverse accessor 'Permission.user_set' for 'auth.User.user_permissions' clashes with reverse accessor for 'users.CustomUser.user_permissions'.
	HINT: Add or change a related_name argument to the definition for 'auth.User.user_permissions' or 'users.CustomUser.user_permissions'.
users.CustomUser.groups: (fields.E304) Reverse accessor 'Group.user_set' for 'users.CustomUser.groups' clashes with reverse accessor for 'auth.User.groups'.
	HINT: Add or change a related_name argument to the definition for 'users.CustomUser.groups' or 'auth.User.groups'.
users.CustomUser.user_permissions: (fields.E304) Reverse accessor 'Permission.user_set' for 'users.CustomUser.user_permissions' clashes with reverse accessor for 'auth.User.user_permissions'.
	HINT: Add or change a related_name argument to the definition for 'users.CustomUser.user_permissions' or 'auth.User.user_permissions'.

System check identified 4 issues (0 silenced).
/home/user/tubonge_project/tubonge_backend/users/models.py changed, reloading.
Performing system checks...

Watching for file changes with StatReloader
Exception in thread django-main-thread:
Traceback (most recent call last):
  File "/usr/local/lib/python3.10/dist-packages/django/db/backends/base/base.py", line 279, in ensure_connection
    self.connect()
  File "/usr/local/lib/python3.10/dist-packages/django/utils/asyncio.py", line 26, in inner
    return func(*args, **kwargs)
  File "/usr/local/lib/python3.10/dist-packages/django/db/backends/base/base.py", line 256, in connect
    self.connection = self.get_new_connection(conn_params)
  File "/usr/local/lib/python3.10/dist-packages/django/utils/asyncio.py", line 26, in inner
    return func(*args, **kwargs)
  File "/usr/local/lib/python3.10/dist-packages/django/db/backends/postgresql/base.py", line 332, in get_new_connection
    connection = self.Database.connect(**conn_params)
  File "/usr/local/lib/python3.10/dist-packages/psycopg2/__init__.py", line 122, in connect
    conn = _connect(dsn, connection_factory=connection_factory, **kwasync)
psycopg2.OperationalError: connection to server at "localhost" (127.0.0.1), port 5432 failed: FATAL:  password authentication failed for user "your_db_user"
connection to server at "localhost" (127.0.0.1), port 5432 failed: FATAL:  password authentication failed for user "your_db_user"


The above exception was the direct cause of the following exception:

Traceback (most recent call last):
  File "/usr/lib/python3.10/threading.py", line 1016, in _bootstrap_inner
    self.run()
  File "/usr/lib/python3.10/threading.py", line 953, in run
    self._target(*self._args, **self._kwargs)
  File "/usr/local/lib/python3.10/dist-packages/django/utils/autoreload.py", line 64, in wrapper
    fn(*args, **kwargs)
  File "/usr/local/lib/python3.10/dist-packages/django/core/management/commands/runserver.py", line 137, in inner_run
    self.check_migrations()
  File "/usr/local/lib/python3.10/dist-packages/django/core/management/base.py", line 581, in check_migrations
    executor = MigrationExecutor(connections[DEFAULT_DB_ALIAS])
  File "/usr/local/lib/python3.10/dist-packages/django/db/migrations/executor.py", line 18, in __init__
    self.loader = MigrationLoader(self.connection)
  File "/usr/local/lib/python3.10/dist-packages/django/db/migrations/loader.py", line 58, in __init__
    self.build_graph()
  File "/usr/local/lib/python3.10/dist-packages/django/db/migrations/loader.py", line 235, in build_graph
    self.applied_migrations = recorder.applied_migrations()
  File "/usr/local/lib/python3.10/dist-packages/django/db/migrations/recorder.py", line 89, in applied_migrations
    if self.has_table():
  File "/usr/local/lib/python3.10/dist-packages/django/db/migrations/recorder.py", line 63, in has_table
    with self.connection.cursor() as cursor:
  File "/usr/local/lib/python3.10/dist-packages/django/utils/asyncio.py", line 26, in inner
    return func(*args, **kwargs)
  File "/usr/local/lib/python3.10/dist-packages/django/db/backends/base/base.py", line 320, in cursor
    return self._cursor()
  File "/usr/local/lib/python3.10/dist-packages/django/db/backends/base/base.py", line 296, in _cursor
    self.ensure_connection()
  File "/usr/local/lib/python3.10/dist-packages/django/utils/asyncio.py", line 26, in inner
    return func(*args, **kwargs)
  File "/usr/local/lib/python3.10/dist-packages/django/db/backends/base/base.py", line 278, in ensure_connection
    with self.wrap_database_errors:
  File "/usr/local/lib/python3.10/dist-packages/django/db/utils.py", line 91, in __exit__
    raise dj_exc_value.with_traceback(traceback) from exc_value
  File "/usr/local/lib/python3.10/dist-packages/django/db/backends/base/base.py", line 279,Watching for file changes with StatReloader
Exception in thread django-main-thread:
Traceback (most recent call last):
  File "/usr/local/lib/python3.10/dist-packages/django/db/backends/base/base.py", line 279, in ensure_connection
    self.connect()
  File "/usr/local/lib/python3.10/dist-packages/django/utils/asyncio.py", line 26, in inner
    return func(*args, **kwargs)
  File "/usr/local/lib/python3.10/dist-packages/django/db/backends/base/base.py", line 256, in connect
    self.connection = self.get_new_connection(conn_params)
  File "/usr/local/lib/python3.10/dist-packages/django/utils/asyncio.py", line 26, in inner
    return func(*args, **kwargs)
  File "/usr/local/lib/python3.10/dist-packages/django/db/backends/postgresql/base.py", line 332, in get_new_connection
    connection = self.Database.connect(**conn_params)
  File "/usr/local/lib/python3.10/dist-packages/psycopg2/__init__.py", line 122, in connect
    conn = _connect(dsn, connection_factory=connection_factory, **kwasync)
psycopg2.OperationalError: connection to server at "localhost" (127.0.0.1), port 5432 failed: FATAL:  password authentication failed for user "your_db_user"
connection to server at "localhost" (127.0.0.1), port 5432 failed: FATAL:  password authentication failed for user "your_db_user"


The above exception was the direct cause of the following exception:

Traceback (most recent call last):
  File "/usr/lib/python3.10/threading.py", line 1016, in _bootstrap_inner
    self.run()
  File "/usr/lib/python3.10/threading.py", line 953, in run
    self._target(*self._args, **self._kwargs)
  File "/usr/local/lib/python3.10/dist-packages/django/utils/autoreload.py", line 64, in wrapper
    fn(*args, **kwargs)
  File "/usr/local/lib/python3.10/dist-packages/django/core/management/commands/runserver.py", line 137, in inner_run
    self.check_migrations()
  File "/usr/local/lib/python3.10/dist-packages/django/core/management/base.py", line 581, in check_migrations
    executor = MigrationExecutor(connections[DEFAULT_DB_ALIAS])
  File "/usr/local/lib/python3.10/dist-packages/django/db/migrations/executor.py", line 18, in __init__
    self.loader = MigrationLoader(self.connection)
  File "/usr/local/lib/python3.10/dist-packages/django/db/migrations/loader.py", line 58, in __init__
    self.build_graph()
  File "/usr/local/lib/python3.10/dist-packages/django/db/migrations/loader.py", line 235, in build_graph
    self.applied_migrations = recorder.applied_migrations()
  File "/usr/local/lib/python3.10/dist-packages/django/db/migrations/recorder.py", line 89, in applied_migrations
    if self.has_table():
  File "/usr/local/lib/python3.10/dist-packages/django/db/migrations/recorder.py", line 63, in has_table
    with self.connection.cursor() as cursor:
  File "/usr/local/lib/python3.10/dist-packages/django/utils/asyncio.py", line 26, in inner
    return func(*args, **kwargs)
  File "/usr/local/lib/python3.10/dist-packages/django/db/backends/base/base.py", line 320, in cursor
    return self._cursor()
  File "/usr/local/lib/python3.10/dist-packages/django/db/backends/base/base.py", line 296, in _cursor
    self.ensure_connection()
  File "/usr/local/lib/python3.10/dist-packages/django/utils/asyncio.py", line 26, in inner
    return func(*args, **kwargs)
  File "/usr/local/lib/python3.10/dist-packages/django/db/backends/base/base.py", line 278, in ensure_connection
    with self.wrap_database_errors:
  File "/usr/local/lib/python3.10/dist-packages/django/db/utils.py", line 91, in __exit__
    raise dj_exc_value.with_traceback(traceback) from exc_value
  File "/usr/local/lib/python3.10/dist-packages/django/db/backends/base/base.py", line 279, in ensure_connection
    self.connect()
  File "/usr/local/lib/python3.10/dist-packages/django/utils/asyncio.py", line 26, in inner
    return func(*args, **kwargs)
  File "/usr/local/lib/python3.10/dist-packages/django/db/backends/base/base.py", line 256, in connect
    self.connection = self.get_new_connection(conn_params)
  File "/usr/local/lib/python3.10/dist-packages/django/utils/asyncio.py", line 26, in inner
    return func(*args, **kwargs)
  File "/usr/local/lib/python3.10/dist-packages/django/db/backends/postgresql/base.py", line 332, in get_new_connection
    connection = self.Database.connect(**conn_params)
  File "/usr/local/lib/python3.10/dist-packages/psycopg2/__init__.py", line 122, in connect
    conn = _connect(dsn, connection_factory=connection_factory, **kwasync)
django.db.utils.OperationalError: connection to server at "localhost" (127.0.0.1), port 5432 failed: FATAL:  password authentication failed for user "your_db_user"
connection to server at "localhost" (127.0.0.1), port 5432 failed: FATAL:  password authentication failed for user "your_db_user"

